ChromaDB Server Log - 2025-07-12 00:24:43
Command: C:\Program Files\Python310\python.exe -m chromadb.cli.cli run --host localhost --port 8000 --path ./chromadb_data --log-config-path
==================================================
Traceback (most recent call last):
  File "C:\Users\thien\AppData\Roaming\Python\Python310\site-packages\pydantic\v1\env_settings.py", line 198, in __call__
    env_val = settings.__config__.parse_env_var(field.name, env_val)
  File "C:\Users\thien\AppData\Roaming\Python\Python310\site-packages\pydantic\v1\env_settings.py", line 132, in parse_env_var
    return cls.json_loads(raw_val)
  File "C:\Program Files\Python310\lib\json\__init__.py", line 346, in loads
    return _default_decoder.decode(s)
  File "C:\Program Files\Python310\lib\json\decoder.py", line 337, in decode
    obj, end = self.raw_decode(s, idx=_w(s, 0).end())
  File "C:\Program Files\Python310\lib\json\decoder.py", line 355, in raw_decode
    raise JSONDecodeError("Expecting value", s, err.value) from None
json.decoder.JSONDecodeError: Expecting value: line 1 column 1 (char 0)

The above exception was the direct cause of the following exception:

Traceback (most recent call last):
  File "C:\Program Files\Python310\lib\runpy.py", line 187, in _run_module_as_main
    mod_name, mod_spec, code = _get_module_details(mod_name, _Error)
  File "C:\Program Files\Python310\lib\runpy.py", line 110, in _get_module_details
    __import__(pkg_name)
  File "C:\Users\thien\AppData\Roaming\Python\Python310\site-packages\chromadb\__init__.py", line 3, in <module>
    from chromadb.api.client import Client as ClientCreator
  File "C:\Users\thien\AppData\Roaming\Python\Python310\site-packages\chromadb\api\client.py", line 13, in <module>
    from chromadb.api.shared_system_client import SharedSystemClient
  File "C:\Users\thien\AppData\Roaming\Python\Python310\site-packages\chromadb\api\shared_system_client.py", line 10, in <module>
    class SharedSystemClient:
  File "C:\Users\thien\AppData\Roaming\Python\Python310\site-packages\chromadb\api\shared_system_client.py", line 16, in SharedSystemClient
    settings: Settings = Settings(),
  File "C:\Users\thien\AppData\Roaming\Python\Python310\site-packages\pydantic\v1\env_settings.py", line 41, in __init__
    **__pydantic_self__._build_values(
  File "C:\Users\thien\AppData\Roaming\Python\Python310\site-packages\pydantic\v1\env_settings.py", line 76, in _build_values
    return deep_update(*reversed([source(self) for source in sources]))
  File "C:\Users\thien\AppData\Roaming\Python\Python310\site-packages\pydantic\v1\env_settings.py", line 76, in <listcomp>
    return deep_update(*reversed([source(self) for source in sources]))
  File "C:\Users\thien\AppData\Roaming\Python\Python310\site-packages\pydantic\v1\env_settings.py", line 201, in __call__
    raise SettingsError(f'error parsing env var "{env_name}"') from e
pydantic.v1.env_settings.SettingsError: error parsing env var "chroma_server_cors_allow_origins"
